<?xml version="1.0" encoding="utf-8"?>
<!-- This URDF was automatically created by SolidWorks to URDF Exporter! Originally created by Stephen Brawner (brawner@gmail.com) 
     Commit Version: 1.5.1-0-g916b5db  Build Version: 1.5.7152.31018
     For more information, please see http://wiki.ros.org/sw_urdf_exporter -->
<robot
  name="leg-robot">
  <link
    name="base_link">
    <inertial>
      <origin
        xyz="0.134813765788668 0.251830487950379 0.328284243418892"
        rpy="0 0 0" />
      <mass
        value="2.40178438957882" />
      <inertia
        ixx="0.00707686723712239"
        ixy="-2.7324981052748E-07"
        ixz="1.93369863031313E-07"
        iyy="0.0154854586726812"
        iyz="-1.20715159319689E-07"
        izz="0.0095910420638153" />
    </inertial>
    <visual>
      <origin
        xyz="0 0 0"
        rpy="0 0 0" />
      <geometry>
        <mesh
          filename="package://leg-robot/meshes/base_link.STL" />
      </geometry>
      <material
        name="">
        <color
          rgba="0.792156862745098 0.819607843137255 0.933333333333333 1" />
      </material>
    </visual>
    <collision>
      <origin
        xyz="0 0 0"
        rpy="0 0 0" />
      <geometry>
        <mesh
          filename="package://leg-robot/meshes/base_link.STL" />
      </geometry>
    </collision>
  </link>
  <link
    name="llink1">
    <inertial>
      <origin
        xyz="-0.0355211120452005 -0.215484371552082 -1.10573228406796E-06"
        rpy="0 0 0" />
      <mass
        value="0.43136989307321" />
      <inertia
        ixx="0.00261255373009683"
        ixy="-1.54730224764236E-07"
        ixz="-5.46254903304155E-08"
        iyy="0.000204363979846619"
        iyz="-9.79996060279302E-06"
        izz="0.00272660768895071" />
    </inertial>
    <visual>
      <origin
        xyz="0 0 0"
        rpy="0 0 0" />
      <geometry>
        <mesh
          filename="package://leg-robot/meshes/llink1.STL" />
      </geometry>
      <material
        name="">
        <color
          rgba="0.792156862745098 0.819607843137255 0.933333333333333 1" />
      </material>
    </visual>
    <collision>
      <origin
        xyz="0 0 0"
        rpy="0 0 0" />
      <geometry>
        <mesh
          filename="package://leg-robot/meshes/llink1.STL" />
      </geometry>
    </collision>
  </link>
  <joint
    name="ljoint1"
    type="continuous">
    <origin
      xyz="0 -0.289216336885791 0.151524863211464"
      rpy="1.5707963267949 0 0" />
    <parent
      link="base_link" />
    <child
      link="llink1" />
    <axis
      xyz="1 0 0" />
  </joint>
  <link
    name="llink2">
    <inertial>
      <origin
        xyz="-0.0371589792123292 -0.177961893333791 -0.00157862107611334"
        rpy="0 0 0" />
      <mass
        value="0.455413997264765" />
      <inertia
        ixx="0.0026249658638958"
        ixy="-5.35825709937026E-18"
        ixz="-3.99495174909724E-17"
        iyy="0.000232825591707952"
        iyz="4.91487669826941E-06"
        izz="0.00274374190170977" />
    </inertial>
    <visual>
      <origin
        xyz="0 0 0"
        rpy="0 0 0" />
      <geometry>
        <mesh
          filename="package://leg-robot/meshes/llink2.STL" />
      </geometry>
      <material
        name="">
        <color
          rgba="0.792156862745098 0.819607843137255 0.933333333333333 1" />
      </material>
    </visual>
    <collision>
      <origin
        xyz="0 0 0"
        rpy="0 0 0" />
      <geometry>
        <mesh
          filename="package://leg-robot/meshes/llink2.STL" />
      </geometry>
    </collision>
  </link>
  <joint
    name="ljoint2"
    type="continuous">
    <origin
      xyz="0 -0.438 0"
      rpy="0 0 0" />
    <parent
      link="llink1" />
    <child
      link="llink2" />
    <axis
      xyz="1 0 0" />
  </joint>
  <link
    name="llink3">
    <inertial>
      <origin
        xyz="-0.0350562974020015 -0.0366754335013656 0.0493309634273081"
        rpy="0 0 0" />
      <mass
        value="0.291189773826857" />
      <inertia
        ixx="0.000610485905391525"
        ixy="1.3662509487467E-07"
        ixz="-9.66829387673121E-08"
        iyy="0.000684347300419343"
        iyz="-6.03575796727452E-08"
        izz="0.000116061793166679" />
    </inertial>
    <visual>
      <origin
        xyz="0 0 0"
        rpy="0 0 0" />
      <geometry>
        <mesh
          filename="package://leg-robot/meshes/llink3.STL" />
      </geometry>
      <material
        name="">
        <color
          rgba="0.792156862745098 0.819607843137255 0.933333333333333 1" />
      </material>
    </visual>
    <collision>
      <origin
        xyz="0 0 0"
        rpy="0 0 0" />
      <geometry>
        <mesh
          filename="package://leg-robot/meshes/llink3.STL" />
      </geometry>
    </collision>
  </link>
  <joint
    name="ljoint3"
    type="continuous">
    <origin
      xyz="0 -0.44 0"
      rpy="0 0 0" />
    <parent
      link="llink2" />
    <child
      link="llink3" />
    <axis
      xyz="1 0 0" />
  </joint>
  <link
    name="rlink1">
    <inertial>
      <origin
        xyz="0.0560836371363369 -0.215484371552082 -1.10573228401245E-06"
        rpy="0 0 0" />
      <mass
        value="0.431369893073211" />
      <inertia
        ixx="0.00261255373009684"
        ixy="-1.54730224764534E-07"
        ixz="-5.46254903304719E-08"
        iyy="0.000204363979846619"
        iyz="-9.79996060279389E-06"
        izz="0.00272660768895072" />
    </inertial>
    <visual>
      <origin
        xyz="0 0 0"
        rpy="0 0 0" />
      <geometry>
        <mesh
          filename="package://leg-robot/meshes/rlink1.STL" />
      </geometry>
      <material
        name="">
        <color
          rgba="0.792156862745098 0.819607843137255 0.933333333333333 1" />
      </material>
    </visual>
    <collision>
      <origin
        xyz="0 0 0"
        rpy="0 0 0" />
      <geometry>
        <mesh
          filename="package://leg-robot/meshes/rlink1.STL" />
      </geometry>
    </collision>
  </link>
  <joint
    name="rjoint1"
    type="continuous">
    <origin
      xyz="0.2484 -0.28922 0.15152"
      rpy="1.5708 0 0" />
    <parent
      link="base_link" />
    <child
      link="rlink1" />
    <axis
      xyz="1 0 0" />
  </joint>
  <link
    name="rlink2">
    <inertial>
      <origin
        xyz="0.0544457699692059 -0.177961893333791 -0.0015786210761134"
        rpy="0 0 0" />
      <mass
        value="0.455413997264766" />
      <inertia
        ixx="0.00262496586389581"
        ixy="-4.67323958867959E-18"
        ixz="-3.98798316860734E-17"
        iyy="0.000232825591707953"
        iyz="4.91487669826944E-06"
        izz="0.00274374190170978" />
    </inertial>
    <visual>
      <origin
        xyz="0 0 0"
        rpy="0 0 0" />
      <geometry>
        <mesh
          filename="package://leg-robot/meshes/rlink2.STL" />
      </geometry>
      <material
        name="">
        <color
          rgba="0.792156862745098 0.819607843137255 0.933333333333333 1" />
      </material>
    </visual>
    <collision>
      <origin
        xyz="0 0 0"
        rpy="0 0 0" />
      <geometry>
        <mesh
          filename="package://leg-robot/meshes/rlink2.STL" />
      </geometry>
    </collision>
  </link>
  <joint
    name="rjoint2"
    type="continuous">
    <origin
      xyz="0 -0.438 0"
      rpy="0 0 0" />
    <parent
      link="rlink1" />
    <child
      link="rlink2" />
    <axis
      xyz="1 0 0" />
  </joint>
  <link
    name="rlink3">
    <inertial>
      <origin
        xyz="0.0491984517795271 -0.0366754335013656 0.0493309634273082"
        rpy="0 0 0" />
      <mass
        value="0.291189773826857" />
      <inertia
        ixx="0.000610485905391525"
        ixy="1.36625094874639E-07"
        ixz="-9.66829387673132E-08"
        iyy="0.000684347300419342"
        iyz="-6.03575796727496E-08"
        izz="0.000116061793166678" />
    </inertial>
    <visual>
      <origin
        xyz="0 0 0"
        rpy="0 0 0" />
      <geometry>
        <mesh
          filename="package://leg-robot/meshes/rlink3.STL" />
      </geometry>
      <material
        name="">
        <color
          rgba="0.792156862745098 0.819607843137255 0.933333333333333 1" />
      </material>
    </visual>
    <collision>
      <origin
        xyz="0 0 0"
        rpy="0 0 0" />
      <geometry>
        <mesh
          filename="package://leg-robot/meshes/rlink3.STL" />
      </geometry>
    </collision>
  </link>
  <joint
    name="rjoint3"
    type="continuous">
    <origin
      xyz="0.00735000000000655 -0.44 0"
      rpy="0 0 0" />
    <parent
      link="rlink2" />
    <child
      link="rlink3" />
    <axis
      xyz="1 0 0" />
  </joint>
</robot>